{"trial_id": "0001", "hyperparameters": {"space": [{"class_name": "Int", "config": {"name": "embedding_output_dim", "default": null, "conditions": [], "min_value": 5, "max_value": 50, "step": 5, "sampling": "linear"}}, {"class_name": "Int", "config": {"name": "num_layers", "default": null, "conditions": [], "min_value": 1, "max_value": 3, "step": 1, "sampling": "linear"}}, {"class_name": "Int", "config": {"name": "units_0", "default": null, "conditions": [], "min_value": 32, "max_value": 512, "step": 32, "sampling": "linear"}}, {"class_name": "Int", "config": {"name": "units_1", "default": null, "conditions": [], "min_value": 32, "max_value": 512, "step": 32, "sampling": "linear"}}, {"class_name": "Int", "config": {"name": "units_2", "default": null, "conditions": [], "min_value": 32, "max_value": 512, "step": 32, "sampling": "linear"}}], "values": {"embedding_output_dim": 35, "num_layers": 3, "units_0": 32, "tuner/epochs": 3, "tuner/initial_epoch": 0, "tuner/bracket": 2, "tuner/round": 0, "units_1": 32, "units_2": 32}}, "metrics": {"metrics": {}}, "score": null, "best_step": 0, "status": "FAILED", "message": "Traceback (most recent call last):\n  File \"/home/alumnadotarde/anaconda3/lib/python3.12/site-packages/keras_tuner/engine/base_tuner.py\", line 274, in _try_run_and_update_trial\n    self._run_and_update_trial(trial, *fit_args, **fit_kwargs)\n  File \"/home/alumnadotarde/anaconda3/lib/python3.12/site-packages/keras_tuner/engine/base_tuner.py\", line 239, in _run_and_update_trial\n    results = self.run_trial(trial, *fit_args, **fit_kwargs)\n              ^^^^^^^^^^^^^^^^^^^^^^^^^^^^^^^^^^^^^^^^^^^^^^\n  File \"/home/alumnadotarde/anaconda3/lib/python3.12/site-packages/keras_tuner/tuners/hyperband.py\", line 427, in run_trial\n    return super().run_trial(trial, *fit_args, **fit_kwargs)\n           ^^^^^^^^^^^^^^^^^^^^^^^^^^^^^^^^^^^^^^^^^^^^^^^^^\n  File \"/home/alumnadotarde/anaconda3/lib/python3.12/site-packages/keras_tuner/engine/tuner.py\", line 314, in run_trial\n    obj_value = self._build_and_fit_model(trial, *args, **copied_kwargs)\n                ^^^^^^^^^^^^^^^^^^^^^^^^^^^^^^^^^^^^^^^^^^^^^^^^^^^^^^^^\n  File \"/home/alumnadotarde/anaconda3/lib/python3.12/site-packages/keras_tuner/engine/tuner.py\", line 233, in _build_and_fit_model\n    results = self.hypermodel.fit(hp, model, *args, **kwargs)\n              ^^^^^^^^^^^^^^^^^^^^^^^^^^^^^^^^^^^^^^^^^^^^^^^\n  File \"/home/alumnadotarde/anaconda3/lib/python3.12/site-packages/keras_tuner/engine/hypermodel.py\", line 149, in fit\n    return model.fit(*args, **kwargs)\n           ^^^^^^^^^^^^^^^^^^^^^^^^^^\n  File \"/home/alumnadotarde/anaconda3/lib/python3.12/site-packages/keras/src/utils/traceback_utils.py\", line 122, in error_handler\n    raise e.with_traceback(filtered_tb) from None\n  File \"/home/alumnadotarde/anaconda3/lib/python3.12/site-packages/tensorflow/python/eager/execute.py\", line 59, in quick_execute\n    except TypeError as e:\ntensorflow.python.framework.errors_impl.InvalidArgumentError: Graph execution error:\n\nDetected at node functional_1/embedding_1/GatherV2 defined at (most recent call last):\n  File \"<frozen runpy>\", line 198, in _run_module_as_main\n\n  File \"<frozen runpy>\", line 88, in _run_code\n\n  File \"/home/alumnadotarde/anaconda3/lib/python3.12/site-packages/ipykernel_launcher.py\", line 17, in <module>\n\n  File \"/home/alumnadotarde/anaconda3/lib/python3.12/site-packages/traitlets/config/application.py\", line 1075, in launch_instance\n\n  File \"/home/alumnadotarde/anaconda3/lib/python3.12/site-packages/ipykernel/kernelapp.py\", line 701, in start\n\n  File \"/home/alumnadotarde/anaconda3/lib/python3.12/site-packages/tornado/platform/asyncio.py\", line 205, in start\n\n  File \"/home/alumnadotarde/anaconda3/lib/python3.12/asyncio/base_events.py\", line 641, in run_forever\n\n  File \"/home/alumnadotarde/anaconda3/lib/python3.12/asyncio/base_events.py\", line 1987, in _run_once\n\n  File \"/home/alumnadotarde/anaconda3/lib/python3.12/asyncio/events.py\", line 88, in _run\n\n  File \"/home/alumnadotarde/anaconda3/lib/python3.12/site-packages/ipykernel/kernelbase.py\", line 534, in dispatch_queue\n\n  File \"/home/alumnadotarde/anaconda3/lib/python3.12/site-packages/ipykernel/kernelbase.py\", line 523, in process_one\n\n  File \"/home/alumnadotarde/anaconda3/lib/python3.12/site-packages/ipykernel/kernelbase.py\", line 429, in dispatch_shell\n\n  File \"/home/alumnadotarde/anaconda3/lib/python3.12/site-packages/ipykernel/kernelbase.py\", line 767, in execute_request\n\n  File \"/home/alumnadotarde/anaconda3/lib/python3.12/site-packages/ipykernel/ipkernel.py\", line 429, in do_execute\n\n  File \"/home/alumnadotarde/anaconda3/lib/python3.12/site-packages/ipykernel/zmqshell.py\", line 549, in run_cell\n\n  File \"/home/alumnadotarde/anaconda3/lib/python3.12/site-packages/IPython/core/interactiveshell.py\", line 3075, in run_cell\n\n  File \"/home/alumnadotarde/anaconda3/lib/python3.12/site-packages/IPython/core/interactiveshell.py\", line 3130, in _run_cell\n\n  File \"/home/alumnadotarde/anaconda3/lib/python3.12/site-packages/IPython/core/async_helpers.py\", line 129, in _pseudo_sync_runner\n\n  File \"/home/alumnadotarde/anaconda3/lib/python3.12/site-packages/IPython/core/interactiveshell.py\", line 3334, in run_cell_async\n\n  File \"/home/alumnadotarde/anaconda3/lib/python3.12/site-packages/IPython/core/interactiveshell.py\", line 3517, in run_ast_nodes\n\n  File \"/home/alumnadotarde/anaconda3/lib/python3.12/site-packages/IPython/core/interactiveshell.py\", line 3577, in run_code\n\n  File \"/tmp/ipykernel_85312/4022103272.py\", line 36, in <module>\n\n  File \"/home/alumnadotarde/anaconda3/lib/python3.12/site-packages/keras_tuner/engine/base_tuner.py\", line 234, in search\n\n  File \"/home/alumnadotarde/anaconda3/lib/python3.12/site-packages/keras_tuner/engine/base_tuner.py\", line 274, in _try_run_and_update_trial\n\n  File \"/home/alumnadotarde/anaconda3/lib/python3.12/site-packages/keras_tuner/engine/base_tuner.py\", line 239, in _run_and_update_trial\n\n  File \"/home/alumnadotarde/anaconda3/lib/python3.12/site-packages/keras_tuner/tuners/hyperband.py\", line 427, in run_trial\n\n  File \"/home/alumnadotarde/anaconda3/lib/python3.12/site-packages/keras_tuner/engine/tuner.py\", line 314, in run_trial\n\n  File \"/home/alumnadotarde/anaconda3/lib/python3.12/site-packages/keras_tuner/engine/tuner.py\", line 233, in _build_and_fit_model\n\n  File \"/home/alumnadotarde/anaconda3/lib/python3.12/site-packages/keras_tuner/engine/hypermodel.py\", line 149, in fit\n\n  File \"/home/alumnadotarde/anaconda3/lib/python3.12/site-packages/keras/src/utils/traceback_utils.py\", line 117, in error_handler\n\n  File \"/home/alumnadotarde/anaconda3/lib/python3.12/site-packages/keras/src/backend/tensorflow/trainer.py\", line 371, in fit\n\n  File \"/home/alumnadotarde/anaconda3/lib/python3.12/site-packages/keras/src/backend/tensorflow/trainer.py\", line 219, in function\n\n  File \"/home/alumnadotarde/anaconda3/lib/python3.12/site-packages/keras/src/backend/tensorflow/trainer.py\", line 132, in multi_step_on_iterator\n\n  File \"/home/alumnadotarde/anaconda3/lib/python3.12/site-packages/keras/src/backend/tensorflow/trainer.py\", line 113, in one_step_on_data\n\n  File \"/home/alumnadotarde/anaconda3/lib/python3.12/site-packages/keras/src/backend/tensorflow/trainer.py\", line 57, in train_step\n\n  File \"/home/alumnadotarde/anaconda3/lib/python3.12/site-packages/keras/src/utils/traceback_utils.py\", line 117, in error_handler\n\n  File \"/home/alumnadotarde/anaconda3/lib/python3.12/site-packages/keras/src/layers/layer.py\", line 908, in __call__\n\n  File \"/home/alumnadotarde/anaconda3/lib/python3.12/site-packages/keras/src/utils/traceback_utils.py\", line 117, in error_handler\n\n  File \"/home/alumnadotarde/anaconda3/lib/python3.12/site-packages/keras/src/ops/operation.py\", line 46, in __call__\n\n  File \"/home/alumnadotarde/anaconda3/lib/python3.12/site-packages/keras/src/utils/traceback_utils.py\", line 156, in error_handler\n\n  File \"/home/alumnadotarde/anaconda3/lib/python3.12/site-packages/keras/src/models/functional.py\", line 182, in call\n\n  File \"/home/alumnadotarde/anaconda3/lib/python3.12/site-packages/keras/src/ops/function.py\", line 171, in _run_through_graph\n\n  File \"/home/alumnadotarde/anaconda3/lib/python3.12/site-packages/keras/src/models/functional.py\", line 637, in call\n\n  File \"/home/alumnadotarde/anaconda3/lib/python3.12/site-packages/keras/src/utils/traceback_utils.py\", line 117, in error_handler\n\n  File \"/home/alumnadotarde/anaconda3/lib/python3.12/site-packages/keras/src/layers/layer.py\", line 908, in __call__\n\n  File \"/home/alumnadotarde/anaconda3/lib/python3.12/site-packages/keras/src/utils/traceback_utils.py\", line 117, in error_handler\n\n  File \"/home/alumnadotarde/anaconda3/lib/python3.12/site-packages/keras/src/ops/operation.py\", line 46, in __call__\n\n  File \"/home/alumnadotarde/anaconda3/lib/python3.12/site-packages/keras/src/utils/traceback_utils.py\", line 156, in error_handler\n\n  File \"/home/alumnadotarde/anaconda3/lib/python3.12/site-packages/keras/src/layers/core/embedding.py\", line 140, in call\n\n  File \"/home/alumnadotarde/anaconda3/lib/python3.12/site-packages/keras/src/ops/numpy.py\", line 5346, in take\n\n  File \"/home/alumnadotarde/anaconda3/lib/python3.12/site-packages/keras/src/backend/tensorflow/numpy.py\", line 2093, in take\n\nindices[6,0] = 139 is not in [0, 133)\n\t [[{{node functional_1/embedding_1/GatherV2}}]] [Op:__inference_multi_step_on_iterator_2990]\n"}